Workbook

Sheet Ürünler
A1: Barkod | B1: Yayın | C1: Sınıf | D1: Ders | E1: Genel Tür | F1: Tür | G1: Fiyat | H1: İnd | I1: Toplu | J1: Tanıtım Linki | K1: Yeni Barkodlar
A2: 9786256648630 | B2: Apotemi Yayınları | C2: Maarif TYT | D2: Türkçe | E2: Paragraf | F2: Soru Bankası | G2: 509 | H2: =IF(SUMIFS(İndirimler!$C$2:$C$210,İndirimler!$A$2:$A$210,B2,İndirimler!$B$2:$B$210,C2)>0,ROUND(G2*(1-SUMIFS(İndirimler!$C$2:$C$210,İndirimler!$A$2:$A$210,B2,İndirimler!$B$2:$B$210,C2)),2),"") -> 432.65 | I2: =IF(SUMIFS(İndirimler!$D$2:$D$210,İndirimler!$A$2:$A$210,B2,İndirimler!$B$2:$B$210,C2)>0,ROUND(G2*(1-SUMIFS(İndirimler!$D$2:$D$210,İndirimler!$A$2:$A$210,B2,İndirimler!$B$2:$B$210,C2)),2),"") -> 356.3
A3: 9786256712614 | B3: Bilgi Sarmal Yayınları | C3: Maarif TYT | D3: Türkçe | F3: Soru Bankası | G3: 539 | H3: =IF(SUMIFS(İndirimler!$C$2:$C$210,İndirimler!$A$2:$A$210,B3,İndirimler!$B$2:$B$210,C3)>0,ROUND(G3*(1-SUMIFS(İndirimler!$C$2:$C$210,İndirimler!$A$2:$A$210,B3,İndirimler!$B$2:$B$210,C3)),2),"") -> 458.15 | I3: =IF(SUMIFS(İndirimler!$D$2:$D$210,İndirimler!$A$2:$A$210,B3,İndirimler!$B$2:$B$210,C3)>0,ROUND(G3*(1-SUMIFS(İndirimler!$D$2:$D$210,İndirimler!$A$2:$A$210,B3,İndirimler!$B$2:$B$210,C3)),2),"") -> 377.3 | J3: https://online.fliphtml5.com/udqwy/etww/
A4: 9786259206219 | B4: Edebiyat Sokağı Yayınları | C4: Maarif TYT | D4: Türkçe | E4: Paragraf | F4: Soru Bankası | G4: 369 | H4: =IF(SUMIFS(İndirimler!$C$2:$C$210,İndirimler!$A$2:$A$210,B4,İndirimler!$B$2:$B$210,C4)>0,ROUND(G4*(1-SUMIFS(İndirimler!$C$2:$C$210,İndirimler!$A$2:$A$210,B4,İndirimler!$B$2:$B$210,C4)),2),"") -> 313.65 | I4: =IF(SUMIFS(İndirimler!$D$2:$D$210,İndirimler!$A$2:$A$210,B4,İndirimler!$B$2:$B$210,C4)>0,ROUND(G4*(1-SUMIFS(İndirimler!$D$2:$D$210,İndirimler!$A$2:$A$210,B4,İndirimler!$B$2:$B$210,C4)),2),"") -> 258.3
A5: 9786052758861 | B5: Limit | C5: Maarif TYT | D5: Türkçe | F5: Soru Bankası | G5: 480 | H5: =IF(SUMIFS(İndirimler!$C$2:$C$210,İndirimler!$A$2:$A$210,B5,İndirimler!$B$2:$B$210,C5)>0,ROUND(G5*(1-SUMIFS(İndirimler!$C$2:$C$210,İndirimler!$A$2:$A$210,B5,İndirimler!$B$2:$B$210,C5)),2),"") -> 408 | I5: =IF(SUMIFS(İndirimler!$D$2:$D$210,İndirimler!$A$2:$A$210,B5,İndirimler!$B$2:$B$210,C5)>0,ROUND(G5*(1-SUMIFS(İndirimler!$D$2:$D$210,İndirimler!$A$2:$A$210,B5,İndirimler!$B$2:$B$210,C5)),2),"") -> 336
A6: ORNEK00000257 | B6: Mikro Orijinal Yayınları | C6: Maarif TYT | D6: Türkçe | E6: Dil Bilgisi | F6: Soru Bankası | H6: =IF(SUMIFS(İndirimler!$C$2:$C$210,İndirimler!$A$2:$A$210,B6,İndirimler!$B$2:$B$210,C6)>0,ROUND(G6*(1-SUMIFS(İndirimler!$C$2:$C$210,İndirimler!$A$2:$A$210,B6,İndirimler!$B$2:$B$210,C6)),2),"") -> 0 | I6: =IF(SUMIFS(İndirimler!$D$2:$D$210,İndirimler!$A$2:$A$210,B6,İndirimler!$B$2:$B$210,C6)>0,ROUND(G6*(1-SUMIFS(İndirimler!$D$2:$D$210,İndirimler!$A$2:$A$210,B6,İndirimler!$B$2:$B$210,C6)),2),"") -> 0
A7: ORNEK00000263 | B7: Mikro Orijinal Yayınları | C7: Maarif TYT | D7: Türkçe | E7: Mikro | F7: Soru Bankası | H7: =IF(SUMIFS(İndirimler!$C$2:$C$210,İndirimler!$A$2:$A$210,B7,İndirimler!$B$2:$B$210,C7)>0,ROUND(G7*(1-SUMIFS(İndirimler!$C$2:$C$210,İndirimler!$A$2:$A$210,B7,İndirimler!$B$2:$B$210,C7)),2),"") -> 0 | I7: =IF(SUMIFS(İndirimler!$D$2:$D$210,İndirimler!$A$2:$A$210,B7,İndirimler!$B$2:$B$210,C7)>0,ROUND(G7*(1-SUMIFS(İndirimler!$D$2:$D$210,İndirimler!$A$2:$A$210,B7,İndirimler!$B$2:$B$210,C7)),2),"") -> 0
A8: 9786255708427 | B8: Mikro Orijinal Yayınları | C8: Maarif TYT | D8: Türkçe | E8: Yazım ve Noktalama | F8: Soru Bankası | G8: 219 | H8: =IF(SUMIFS(İndirimler!$C$2:$C$210,İndirimler!$A$2:$A$210,B8,İndirimler!$B$2:$B$210,C8)>0,ROUND(G8*(1-SUMIFS(İndirimler!$C$2:$C$210,İndirimler!$A$2:$A$210,B8,İndirimler!$B$2:$B$210,C8)),2),"") -> 186.15 | I8: =IF(SUMIFS(İndirimler!$D$2:$D$210,İndirimler!$A$2:$A$210,B8,İndirimler!$B$2:$B$210,C8)>0,ROUND(G8*(1-SUMIFS(İndirimler!$D$2:$D$210,İndirimler!$A$2:$A$210,B8,İndirimler!$B$2:$B$210,C8)),2),"") -> 153.3
A9: 9786259205748 | B9: Ulti Yayınları | C9: 9. Sınıf | D9: Türk Dili ve Edebiyatı | F9: Fasikül Set | G9: 549 | H9: =IF(SUMIFS(İndirimler!$C$2:$C$210,İndirimler!$A$2:$A$210,B9,İndirimler!$B$2:$B$210,C9)>0,ROUND(G9*(1-SUMIFS(İndirimler!$C$2:$C$210,İndirimler!$A$2:$A$210,B9,İndirimler!$B$2:$B$210,C9)),2),"") -> 466.65 | I9: =IF(SUMIFS(İndirimler!$D$2:$D$210,İndirimler!$A$2:$A$210,B9,İndirimler!$B$2:$B$210,C9)>0,ROUND(G9*(1-SUMIFS(İndirimler!$D$2:$D$210,İndirimler!$A$2:$A$210,B9,İndirimler!$B$2:$B$210,C9)),2),"") -> 384.3 | J9: https://online.fliphtml5.com/kbscf/eahn/
A10: 9786256040229 | B10: Çap Yayınları | C10: 9. Sınıf | D10: Türk Dili ve Edebiyatı | F10: Fasikül Set | G10: 565 | H10: =IF(SUMIFS(İndirimler!$C$2:$C$210,İndirimler!$A$2:$A$210,B10,İndirimler!$B$2:$B$210,C10)>0,ROUND(G10*(1-SUMIFS(İndirimler!$C$2:$C$210,İndirimler!$A$2:$A$210,B10,İndirimler!$B$2:$B$210,C10)),2),"") -> 480.25 | I10: =IF(SUMIFS(İndirimler!$D$2:$D$210,İndirimler!$A$2:$A$210,B10,İndirimler!$B$2:$B$210,C10)>0,ROUND(G10*(1-SUMIFS(İndirimler!$D$2:$D$210,İndirimler!$A$2:$A$210,B10,İndirimler!$B$2:$B$210,C10)),2),"") -> 395.5 | J10: https://online.fliphtml5.com/chncu/mibj/
A11: ORNEK00000036 | B11: Bilgi Sarmal Yayınları | C11: 9. Sınıf | D11: Türk Dili ve Edebiyatı | E11: Tema | F11: Konu Anlatımlı | H11: =IF(SUMIFS(İndirimler!$C$2:$C$210,İndirimler!$A$2:$A$210,B11,İndirimler!$B$2:$B$210,C11)>0,ROUND(G11*(1-SUMIFS(İndirimler!$C$2:$C$210,İndirimler!$A$2:$A$210,B11,İndirimler!$B$2:$B$210,C11)),2),"") -> 0 | I11: =IF(SUMIFS(İndirimler!$D$2:$D$210,İndirimler!$A$2:$A$210,B11,İndirimler!$B$2:$B$210,C11)>0,ROUND(G11*(1-SUMIFS(İndirimler!$D$2:$D$210,İndirimler!$A$2:$A$210,B11,İndirimler!$B$2:$B$210,C11)),2),"") -> 0
A12: 9786256630413 | B12: Eğitim Vadisi | C12: 9. Sınıf | D12: Türk Dili ve Edebiyatı | E12: TAK Tam Anlatım Kitabı | F12: Konu Anlatımlı | G12: 428 | H12: =IF(SUMIFS(İndirimler!$C$2:$C$210,İndirimler!$A$2:$A$210,B12,İndirimler!$B$2:$B$210,C12)>0,ROUND(G12*(1-SUMIFS(İndirimler!$C$2:$C$210,İndirimler!$A$2:$A$210,B12,İndirimler!$B$2:$B$210,C12)),2),"") -> 363.8 | I12: =IF(SUMIFS(İndirimler!$D$2:$D$210,İndirimler!$A$2:$A$210,B12,İndirimler!$B$2:$B$210,C12)>0,ROUND(G12*(1-SUMIFS(İndirimler!$D$2:$D$210,İndirimler!$A$2:$A$210,B12,İndirimler!$B$2:$B$210,C12)),2),"") -> 299.6 | J12: https://app.karakok.net/spShowFlip/1546
A13: 9786052756713 | B13: Limit | C13: 9. Sınıf | D13: Türk Dili ve Edebiyatı | F13: Konu Anlatımlı | G13: 669 | H13: =IF(SUMIFS(İndirimler!$C$2:$C$210,İndirimler!$A$2:$A$210,B13,İndirimler!$B$2:$B$210,C13)>0,ROUND(G13*(1-SUMIFS(İndirimler!$C$2:$C$210,İndirimler!$A$2:$A$210,B13,İndirimler!$B$2:$B$210,C13)),2),"") -> 568.65 | I13: =IF(SUMIFS(İndirimler!$D$2:$D$210,İndirimler!$A$2:$A$210,B13,İndirimler!$B$2:$B$210,C13)>0,ROUND(G13*(1-SUMIFS(İndirimler!$D$2:$D$210,İndirimler!$A$2:$A$210,B13,İndirimler!$B$2:$B$210,C13)),2),"") -> 468.3 | J13: https://online.fliphtml5.com/cotrr/kaoj/
A14: 9786256412958 | B14: Miray | C14: 9. Sınıf | D14: Türk Dili ve Edebiyatı | E14: Ders Anlatım Fasikülleri | F14: Konu Anlatımlı | G14: 800 | H14: =IF(SUMIFS(İndirimler!$C$2:$C$210,İndirimler!$A$2:$A$210,B14,İndirimler!$B$2:$B$210,C14)>0,ROUND(G14*(1-SUMIFS(İndirimler!$C$2:$C$210,İndirimler!$A$2:$A$210,B14,İndirimler!$B$2:$B$210,C14)),2),"") -> 680 | I14: =IF(SUMIFS(İndirimler!$D$2:$D$210,İndirimler!$A$2:$A$210,B14,İndirimler!$B$2:$B$210,C14)>0,ROUND(G14*(1-SUMIFS(İndirimler!$D$2:$D$210,İndirimler!$A$2:$A$210,B14,İndirimler!$B$2:$B$210,C14)),2),"") -> 560
A15: 9786259981284 | B15: Süre Yayınları | C15: 9. Sınıf | D15: Türk Dili ve Edebiyatı | F15: Konu Anlatımlı | G15: 539 | H15: =IF(SUMIFS(İndirimler!$C$2:$C$210,İndirimler!$A$2:$A$210,B15,İndirimler!$B$2:$B$210,C15)>0,ROUND(G15*(1-SUMIFS(İndirimler!$C$2:$C$210,İndirimler!$A$2:$A$210,B15,İndirimler!$B$2:$B$210,C15)),2),"") -> 458.15 | I15: =IF(SUMIFS(İndirimler!$D$2:$D$210,İndirimler!$A$2:$A$210,B15,İndirimler!$B$2:$B$210,C15)>0,ROUND(G15*(1-SUMIFS(İndirimler!$D$2:$D$210,İndirimler!$A$2:$A$210,B15,İndirimler!$B$2:$B$210,C15)),2),"") -> 377.3
A16: 9786256921481 | B16: 4K | C16: 9. Sınıf | D16: Türk Dili ve Edebiyatı | F16: Soru Bankası | G16: 402 | H16: =IF(SUMIFS(İndirimler!$C$2:$C$210,İndirimler!$A$2:$A$210,B16,İndirimler!$B$2:$B$210,C16)>0,ROUND(G16*(1-SUMIFS(İndirimler!$C$2:$C$210,İndirimler!$A$2:$A$210,B16,İndirimler!$B$2:$B$210,C16)),2),"") -> 341.7 | I16: =IF(SUMIFS(İndirimler!$D$2:$D$210,İndirimler!$A$2:$A$210,B16,İndirimler!$B$2:$B$210,C16)>0,ROUND(G16*(1-SUMIFS(İndirimler!$D$2:$D$210,İndirimler!$A$2:$A$210,B16,İndirimler!$B$2:$B$210,C16)),2),"") -> 281.4 | J16: https://app.karakok.net/spShowFlip/2140
A17: 9786256712157 | B17: Bilgi Sarmal Yayınları | C17: 9. Sınıf | D17: Türk Dili ve Edebiyatı | F17: Soru Bankası | G17: 329 | H17: =IF(SUMIFS(İndirimler!$C$2:$C$210,İndirimler!$A$2:$A$210,B17,İndirimler!$B$2:$B$210,C17)>0,ROUND(G17*(1-SUMIFS(İndirimler!$C$2:$C$210,İndirimler!$A$2:$A$210,B17,İndirimler!$B$2:$B$210,C17)),2),"") -> 279.65 | I17: =IF(SUMIFS(İndirimler!$D$2:$D$210,İndirimler!$A$2:$A$210,B17,İndirimler!$B$2:$B$210,C17)>0,ROUND(G17*(1-SUMIFS(İndirimler!$D$2:$D$210,İndirimler!$A$2:$A$210,B17,İndirimler!$B$2:$B$210,C17)),2),"") -> 230.3 | J17: https://online.fliphtml5.com/udqwy/tjur/
A18: 9786256630475 | B18: Eğitim Vadisi | C18: 9. Sınıf | D18: Türk Dili ve Edebiyatı | E18: TİK Tam İzleme Kitabı | F18: Soru Bankası | G18: 428 | H18: =IF(SUMIFS(İndirimler!$C$2:$C$210,İndirimler!$A$2:$A$210,B18,İndirimler!$B$2:$B$210,C18)>0,ROUND(G18*(1-SUMIFS(İndirimler!$C$2:$C$210,İndirimler!$A$2:$A$210,B18,İndirimler!$B$2:$B$210,C18)),2),"") -> 363.8 | I18: =IF(SUMIFS(İndirimler!$D$2:$D$210,İndirimler!$A$2:$A$210,B18,İndirimler!$B$2:$B$210,C18)>0,ROUND(G18*(1-SUMIFS(İndirimler!$D$2:$D$210,İndirimler!$A$2:$A$210,B18,İndirimler!$B$2:$B$210,C18)),2),"") -> 299.6 | J18: https://app.karakok.net/spShowFlip/1553
A19: 9786257532754 | B19: Hız ve Renk Yayınları | C19: 9. Sınıf | D19: Türk Dili ve Edebiyatı | E19: HİT | F19: Soru Bankası | G19: 475 | H19: =IF(SUMIFS(İndirimler!$C$2:$C$210,İndirimler!$A$2:$A$210,B19,İndirimler!$B$2:$B$210,C19)>0,ROUND(G19*(1-SUMIFS(İndirimler!$C$2:$C$210,İndirimler!$A$2:$A$210,B19,İndirimler!$B$2:$B$210,C19)),2),"") -> 403.75 | I19: =IF(SUMIFS(İndirimler!$D$2:$D$210,İndirimler!$A$2:$A$210,B19,İndirimler!$B$2:$B$210,C19)>0,ROUND(G19*(1-SUMIFS(İndirimler!$D$2:$D$210,İndirimler!$A$2:$A$210,B19,İndirimler!$B$2:$B$210,C19)),2),"") -> 332.5 | J19: https://online.fliphtml5.com/udqwy/ftqu/
A20: 9786052756782 | B20: Limit | C20: 9. Sınıf | D20: Türk Dili ve Edebiyatı | F20: Soru Bankası | G20: 626 | H20: =IF(SUMIFS(İndirimler!$C$2:$C$210,İndirimler!$A$2:$A$210,B20,İndirimler!$B$2:$B$210,C20)>0,ROUND(G20*(1-SUMIFS(İndirimler!$C$2:$C$210,İndirimler!$A$2:$A$210,B20,İndirimler!$B$2:$B$210,C20)),2),"") -> 532.1 | I20: =IF(SUMIFS(İndirimler!$D$2:$D$210,İndirimler!$A$2:$A$210,B20,İndirimler!$B$2:$B$210,C20)>0,ROUND(G20*(1-SUMIFS(İndirimler!$D$2:$D$210,İndirimler!$A$2:$A$210,B20,İndirimler!$B$2:$B$210,C20)),2),"") -> 438.2 | J20: https://online.fliphtml5.com/cotrr/cewx/
A21: 9786256412835 | B21: Miray | C21: 9. Sınıf | D21: Türk Dili ve Edebiyatı | E21: Tematik | F21: Soru Bankası | G21: 493 | H21: =IF(SUMIFS(İndirimler!$C$2:$C$210,İndirimler!$A$2:$A$210,B21,İndirimler!$B$2:$B$210,C21)>0,ROUND(G21*(1-SUMIFS(İndirimler!$C$2:$C$210,İndirimler!$A$2:$A$210,B21,İndirimler!$B$2:$B$210,C21)),2),"") -> 419.05 | I21: =IF(SUMIFS(İndirimler!$D$2:$D$210,İndirimler!$A$2:$A$210,B21,İndirimler!$B$2:$B$210,C21)>0,ROUND(G21*(1-SUMIFS(İndirimler!$D$2:$D$210,İndirimler!$A$2:$A$210,B21,İndirimler!$B$2:$B$210,C21)),2),"") -> 345.1
A22: 9786256040502 | B22: Çap Yayınları | C22: 9. Sınıf | D22: Türk Dili ve Edebiyatı | E22: Tematik | F22: Soru Bankası | G22: 519 | H22: =IF(SUMIFS(İndirimler!$C$2:$C$210,İndirimler!$A$2:$A$210,B22,İndirimler!$B$2:$B$210,C22)>0,ROUND(G22*(1-SUMIFS(İndirimler!$C$2:$C$210,İndirimler!$A$2:$A$210,B22,İndirimler!$B$2:$B$210,C22)),2),"") -> 441.15 | I22: =IF(SUMIFS(İndirimler!$D$2:$D$210,İndirimler!$A$2:$A$210,B22,İndirimler!$B$2:$B$210,C22)>0,ROUND(G22*(1-SUMIFS(İndirimler!$D$2:$D$210,İndirimler!$A$2:$A$210,B22,İndirimler!$B$2:$B$210,C22)),2),"") -> 363.3
A23: 9786258160406 | B23: ENS Yayınları | C23: 9. Sınıf | D23: Türk Dili ve Edebiyatı | F23: Etkinlik Kitabı | G23: 329 | H23: =IF(SUMIFS(İndirimler!$C$2:$C$210,İndirimler!$A$2:$A$210,B23,İndirimler!$B$2:$B$210,C23)>0,ROUND(G23*(1-SUMIFS(İndirimler!$C$2:$C$210,İndirimler!$A$2:$A$210,B23,İndirimler!$B$2:$B$210,C23)),2),"") -> 279.65 | I23: =IF(SUMIFS(İndirimler!$D$2:$D$210,İndirimler!$A$2:$A$210,B23,İndirimler!$B$2:$B$210,C23)>0,ROUND(G23*(1-SUMIFS(İndirimler!$D$2:$D$210,İndirimler!$A$2:$A$210,B23,İndirimler!$B$2:$B$210,C23)),2),"") -> 230.3
A24: 9786258160895 | B24: ENS Yayınları | C24: 9. Sınıf | D24: Türk Dili ve Edebiyatı | F24: Etkinlik Kitabı | G24: 429 | H24: =IF(SUMIFS(İndirimler!$C$2:$C$210,İndirimler!$A$2:$A$210,B24,İndirimler!$B$2:$B$210,C24)>0,ROUND(G24*(1-SUMIFS(İndirimler!$C$2:$C$210,İndirimler!$A$2:$A$210,B24,İndirimler!$B$2:$B$210,C24)),2),"") -> 364.65 | I24: =IF(SUMIFS(İndirimler!$D$2:$D$210,İndirimler!$A$2:$A$210,B24,İndirimler!$B$2:$B$210,C24)>0,ROUND(G24*(1-SUMIFS(İndirimler!$D$2:$D$210,İndirimler!$A$2:$A$210,B24,İndirimler!$B$2:$B$210,C24)),2),"") -> 300.3
A25: 9786259052601 | B25: Ulti Yayınları | C25: 10. Sınıf | D25: Türk Dili ve Edebiyatı | F25: Fasikül Set | G25: 529 | H25: =IF(SUMIFS(İndirimler!$C$2:$C$210,İndirimler!$A$2:$A$210,B25,İndirimler!$B$2:$B$210,C25)>0,ROUND(G25*(1-SUMIFS(İndirimler!$C$2:$C$210,İndirimler!$A$2:$A$210,B25,İndirimler!$B$2:$B$210,C25)),2),"") -> 449.65 | I25: =IF(SUMIFS(İndirimler!$D$2:$D$210,İndirimler!$A$2:$A$210,B25,İndirimler!$B$2:$B$210,C25)>0,ROUND(G25*(1-SUMIFS(İndirimler!$D$2:$D$210,İndirimler!$A$2:$A$210,B25,İndirimler!$B$2:$B$210,C25)),2),"") -> 370.3 | J25: https://online.fliphtml5.com/kbscf/nfsd/
A26: 9786256040977 | B26: Çap Yayınları | C26: 10. Sınıf | D26: Türk Dili ve Edebiyatı | F26: Fasikül Set | G26: 589 | H26: =IF(SUMIFS(İndirimler!$C$2:$C$210,İndirimler!$A$2:$A$210,B26,İndirimler!$B$2:$B$210,C26)>0,ROUND(G26*(1-SUMIFS(İndirimler!$C$2:$C$210,İndirimler!$A$2:$A$210,B26,İndirimler!$B$2:$B$210,C26)),2),"") -> 500.65 | I26: =IF(SUMIFS(İndirimler!$D$2:$D$210,İndirimler!$A$2:$A$210,B26,İndirimler!$B$2:$B$210,C26)>0,ROUND(G26*(1-SUMIFS(İndirimler!$D$2:$D$210,İndirimler!$A$2:$A$210,B26,İndirimler!$B$2:$B$210,C26)),2),"") -> 412.3 | J26: https://online.fliphtml5.com/chncu/jgqp/
A27: ORNEK00000040 | B27: Bilgi Sarmal Yayınları | C27: 10. Sınıf | D27: Türk Dili ve Edebiyatı | E27: Tema | F27: Konu Anlatımlı | H27: =IF(SUMIFS(İndirimler!$C$2:$C$210,İndirimler!$A$2:$A$210,B27,İndirimler!$B$2:$B$210,C27)>0,ROUND(G27*(1-SUMIFS(İndirimler!$C$2:$C$210,İndirimler!$A$2:$A$210,B27,İndirimler!$B$2:$B$210,C27)),2),"") -> 0 | I27: =IF(SUMIFS(İndirimler!$D$2:$D$210,İndirimler!$A$2:$A$210,B27,İndirimler!$B$2:$B$210,C27)>0,ROUND(G27*(1-SUMIFS(İndirimler!$D$2:$D$210,İndirimler!$A$2:$A$210,B27,İndirimler!$B$2:$B$210,C27)),2),"") -> 0
A28: 9786256911680 | B28: Eğitim Vadisi | C28: 10. Sınıf | D28: Türk Dili ve Edebiyatı | E28: TAK Tam Anlatım Kitabı | F28: Konu Anlatımlı | G28: 376 | H28: =IF(SUMIFS(İndirimler!$C$2:$C$210,İndirimler!$A$2:$A$210,B28,İndirimler!$B$2:$B$210,C28)>0,ROUND(G28*(1-SUMIFS(İndirimler!$C$2:$C$210,İndirimler!$A$2:$A$210,B28,İndirimler!$B$2:$B$210,C28)),2),"") -> 319.6 | I28: =IF(SUMIFS(İndirimler!$D$2:$D$210,İndirimler!$A$2:$A$210,B28,İndirimler!$B$2:$B$210,C28)>0,ROUND(G28*(1-SUMIFS(İndirimler!$D$2:$D$210,İndirimler!$A$2:$A$210,B28,İndirimler!$B$2:$B$210,C28)),2),"") -> 263.2 | J28: https://app.karakok.net/spShowFlip/2166
A29: 9786052757567 | B29: Limit | C29: 10. Sınıf | D29: Türk Dili ve Edebiyatı | F29: Konu Anlatımlı | G29: 684 | H29: =IF(SUMIFS(İndirimler!$C$2:$C$210,İndirimler!$A$2:$A$210,B29,İndirimler!$B$2:$B$210,C29)>0,ROUND(G29*(1-SUMIFS(İndirimler!$C$2:$C$210,İndirimler!$A$2:$A$210,B29,İndirimler!$B$2:$B$210,C29)),2),"") -> 581.4 | I29: =IF(SUMIFS(İndirimler!$D$2:$D$210,İndirimler!$A$2:$A$210,B29,İndirimler!$B$2:$B$210,C29)>0,ROUND(G29*(1-SUMIFS(İndirimler!$D$2:$D$210,İndirimler!$A$2:$A$210,B29,İndirimler!$B$2:$B$210,C29)),2),"") -> 478.8 | J29: https://online.fliphtml5.com/cotrr/qanl/
A30: 9786256142176 | B30: Miray | C30: 10. Sınıf | D30: Türk Dili ve Edebiyatı | E30: Ders Anlatım Fasikülleri | F30: Konu Anlatımlı | G30: 820 | H30: =IF(SUMIFS(İndirimler!$C$2:$C$210,İndirimler!$A$2:$A$210,B30,İndirimler!$B$2:$B$210,C30)>0,ROUND(G30*(1-SUMIFS(İndirimler!$C$2:$C$210,İndirimler!$A$2:$A$210,B30,İndirimler!$B$2:$B$210,C30)),2),"") -> 697 | I30: =IF(SUMIFS(İndirimler!$D$2:$D$210,İndirimler!$A$2:$A$210,B30,İndirimler!$B$2:$B$210,C30)>0,ROUND(G30*(1-SUMIFS(İndirimler!$D$2:$D$210,İndirimler!$A$2:$A$210,B30,İndirimler!$B$2:$B$210,C30)),2),"") -> 574
A31: 9786256921740 | B31: 4K | C31: 10. Sınıf | D31: Türk Dili ve Edebiyatı | F31: Soru Bankası | G31: 402 | H31: =IF(SUMIFS(İndirimler!$C$2:$C$210,İndirimler!$A$2:$A$210,B31,İndirimler!$B$2:$B$210,C31)>0,ROUND(G31*(1-SUMIFS(İndirimler!$C$2:$C$210,İndirimler!$A$2:$A$210,B31,İndirimler!$B$2:$B$210,C31)),2),"") -> 341.7 | I31: =IF(SUMIFS(İndirimler!$D$2:$D$210,İndirimler!$A$2:$A$210,B31,İndirimler!$B$2:$B$210,C31)>0,ROUND(G31*(1-SUMIFS(İndirimler!$D$2:$D$210,İndirimler!$A$2:$A$210,B31,İndirimler!$B$2:$B$210,C31)),2),"") -> 281.4 | J31: https://app.karakok.net/spShowFlip/1917
A32: 9786256712409 | B32: Bilgi Sarmal Yayınları | C32: 10. Sınıf | D32: Türk Dili ve Edebiyatı | F32: Soru Bankası | G32: 479 | H32: =IF(SUMIFS(İndirimler!$C$2:$C$210,İndirimler!$A$2:$A$210,B32,İndirimler!$B$2:$B$210,C32)>0,ROUND(G32*(1-SUMIFS(İndirimler!$C$2:$C$210,İndirimler!$A$2:$A$210,B32,İndirimler!$B$2:$B$210,C32)),2),"") -> 407.15 | I32: =IF(SUMIFS(İndirimler!$D$2:$D$210,İndirimler!$A$2:$A$210,B32,İndirimler!$B$2:$B$210,C32)>0,ROUND(G32*(1-SUMIFS(İndirimler!$D$2:$D$210,İndirimler!$A$2:$A$210,B32,İndirimler!$B$2:$B$210,C32)),2),"") -> 335.3 | J32: https://online.fliphtml5.com/udqwy/peka/
A33: 9786256457256 | B33: Eğitim Vadisi | C33: 10. Sınıf | D33: Türk Dili ve Edebiyatı | E33: TİK Tam İzleme Kitabı | F33: Soru Bankası | G33: 428 | H33: =IF(SUMIFS(İndirimler!$C$2:$C$210,İndirimler!$A$2:$A$210,B33,İndirimler!$B$2:$B$210,C33)>0,ROUND(G33*(1-SUMIFS(İndirimler!$C$2:$C$210,İndirimler!$A$2:$A$210,B33,İndirimler!$B$2:$B$210,C33)),2),"") -> 363.8 | I33: =IF(SUMIFS(İndirimler!$D$2:$D$210,İndirimler!$A$2:$A$210,B33,İndirimler!$B$2:$B$210,C33)>0,ROUND(G33*(1-SUMIFS(İndirimler!$D$2:$D$210,İndirimler!$A$2:$A$210,B33,İndirimler!$B$2:$B$210,C33)),2),"") -> 299.6 | J33: https://app.karakok.net/spShowFlip/2167
A34: 9786257532914 | B34: Hız ve Renk Yayınları | C34: 10. Sınıf | D34: Türk Dili ve Edebiyatı | E34: HİT | F34: Soru Bankası | G34: 405 | H34: =IF(SUMIFS(İndirimler!$C$2:$C$210,İndirimler!$A$2:$A$210,B34,İndirimler!$B$2:$B$210,C34)>0,ROUND(G34*(1-SUMIFS(İndirimler!$C$2:$C$210,İndirimler!$A$2:$A$210,B34,İndirimler!$B$2:$B$210,C34)),2),"") -> 344.25 | I34: =IF(SUMIFS(İndirimler!$D$2:$D$210,İndirimler!$A$2:$A$210,B34,İndirimler!$B$2:$B$210,C34)>0,ROUND(G34*(1-SUMIFS(İndirimler!$D$2:$D$210,İndirimler!$A$2:$A$210,B34,İndirimler!$B$2:$B$210,C34)),2),"") -> 283.5 | J34: https://online.fliphtml5.com/udqwy/qkos/
A35: 9786052757574 | B35: Limit | C35: 10. Sınıf | D35: Türk Dili ve Edebiyatı | F35: Soru Bankası | G35: 622 | H35: =IF(SUMIFS(İndirimler!$C$2:$C$210,İndirimler!$A$2:$A$210,B35,İndirimler!$B$2:$B$210,C35)>0,ROUND(G35*(1-SUMIFS(İndirimler!$C$2:$C$210,İndirimler!$A$2:$A$210,B35,İndirimler!$B$2:$B$210,C35)),2),"") -> 528.7 | I35: =IF(SUMIFS(İndirimler!$D$2:$D$210,İndirimler!$A$2:$A$210,B35,İndirimler!$B$2:$B$210,C35)>0,ROUND(G35*(1-SUMIFS(İndirimler!$D$2:$D$210,İndirimler!$A$2:$A$210,B35,İndirimler!$B$2:$B$210,C35)),2),"") -> 435.4 | J35: https://online.fliphtml5.com/cotrr/mdzj/
A36: 9786256142190 | B36: Miray | C36: 10. Sınıf | D36: Türk Dili ve Edebiyatı | E36: Tematik | F36: Soru Bankası | G36: 598 | H36: =IF(SUMIFS(İndirimler!$C$2:$C$210,İndirimler!$A$2:$A$210,B36,İndirimler!$B$2:$B$210,C36)>0,ROUND(G36*(1-SUMIFS(İndirimler!$C$2:$C$210,İndirimler!$A$2:$A$210,B36,İndirimler!$B$2:$B$210,C36)),2),"") -> 508.3 | I36: =IF(SUMIFS(İndirimler!$D$2:$D$210,İndirimler!$A$2:$A$210,B36,İndirimler!$B$2:$B$210,C36)>0,ROUND(G36*(1-SUMIFS(İndirimler!$D$2:$D$210,İndirimler!$A$2:$A$210,B36,İndirimler!$B$2:$B$210,C36)),2),"") -> 418.6
A37: 9786259981291 | B37: Süre Yayınları | C37: 10. Sınıf | D37: Türk Dili ve Edebiyatı | F37: Soru Bankası | G37: 539 | H37: =IF(SUMIFS(İndirimler!$C$2:$C$210,İndirimler!$A$2:$A$210,B37,İndirimler!$B$2:$B$210,C37)>0,ROUND(G37*(1-SUMIFS(İndirimler!$C$2:$C$210,İndirimler!$A$2:$A$210,B37,İndirimler!$B$2:$B$210,C37)),2),"") -> 458.15 | I37: =IF(SUMIFS(İndirimler!$D$2:$D$210,İndirimler!$A$2:$A$210,B37,İndirimler!$B$2:$B$210,C37)>0,ROUND(G37*(1-SUMIFS(İndirimler!$D$2:$D$210,İndirimler!$A$2:$A$210,B37,İndirimler!$B$2:$B$210,C37)),2),"") -> 377.3
A38: 9786255801043 | B38: Çap Yayınları | C38: 10. Sınıf | D38: Türk Dili ve Edebiyatı | E38: Tematik | F38: Soru Bankası | G38: 505 | H38: =IF(SUMIFS(İndirimler!$C$2:$C$210,İndirimler!$A$2:$A$210,B38,İndirimler!$B$2:$B$210,C38)>0,ROUND(G38*(1-SUMIFS(İndirimler!$C$2:$C$210,İndirimler!$A$2:$A$210,B38,İndirimler!$B$2:$B$210,C38)),2),"") -> 429.25 | I38: =IF(SUMIFS(İndirimler!$D$2:$D$210,İndirimler!$A$2:$A$210,B38,İndirimler!$B$2:$B$210,C38)>0,ROUND(G38*(1-SUMIFS(İndirimler!$D$2:$D$210,İndirimler!$A$2:$A$210,B38,İndirimler!$B$2:$B$210,C38)),2),"") -> 353.5
A39: 9786258160673 | B39: ENS Yayınları | C39: 10. Sınıf | D39: Türk Dili ve Edebiyatı | F39: Etkinlik Kitabı | G39: 409 | H39: =IF(SUMIFS(İndirimler!$C$2:$C$210,İndirimler!$A$2:$A$210,B39,İndirimler!$B$2:$B$210,C39)>0,ROUND(G39*(1-SUMIFS(İndirimler!$C$2:$C$210,İndirimler!$A$2:$A$210,B39,İndirimler!$B$2:$B$210,C39)),2),"") -> 347.65 | I39: =IF(SUMIFS(İndirimler!$D$2:$D$210,İndirimler!$A$2:$A$210,B39,İndirimler!$B$2:$B$210,C39)>0,ROUND(G39*(1-SUMIFS(İndirimler!$D$2:$D$210,İndirimler!$A$2:$A$210,B39,İndirimler!$B$2:$B$210,C39)),2),"") -> 286.3
A40: ORNEK00000059 | B40: Çap Yayınları | C40: 11. Sınıf | D40: Türk Dili ve Edebiyatı | F40: Fasikül Set | H40: =IF(SUMIFS(İndirimler!$C$2:$C$210,İndirimler!$A$2:$A$210,B40,İndirimler!$B$2:$B$210,C40)>0,ROUND(G40*(1-SUMIFS(İndirimler!$C$2:$C$210,İndirimler!$A$2:$A$210,B40,İndirimler!$B$2:$B$210,C40)),2),"") -> 0 | I40: =IF(SUMIFS(İndirimler!$D$2:$D$210,İndirimler!$A$2:$A$210,B40,İndirimler!$B$2:$B$210,C40)>0,ROUND(G40*(1-SUMIFS(İndirimler!$D$2:$D$210,İndirimler!$A$2:$A$210,B40,İndirimler!$B$2:$B$210,C40)),2),"") -> 0
...

Sheet İndirimler
A1: Yayın | B1: Sınıf | C1: Tekli İndirim % | D1: Toplu İndirim %
A2: 4K | B2: 10. Sınıf | C2: 0.15 | D2: 0.3
A3: 4K | B3: 11. Sınıf | C3: 0.15 | D3: 0.3
A4: 4K | B4: 9. Sınıf | C4: 0.15 | D4: 0.3
A5: Acil Yayınları | B5: 10. Sınıf | C5: 0.15 | D5: 0.3
A6: Acil Yayınları | B6: 11. Sınıf | C6: 0.15 | D6: 0.3
A7: Acil Yayınları | B7: 12. Sınıf | C7: 0.15 | D7: 0.3
A8: Acil Yayınları | B8: 9. Sınıf | C8: 0.15 | D8: 0.3
A9: Acil Yayınları | B9: Maarif TYT | C9: 0.15 | D9: 0.3
A10: Aktif Öğrenme Yayınları | B10: 10. Sınıf | C10: 0.15 | D10: 0.3
A11: Aktif Öğrenme Yayınları | B11: 11. Sınıf | C11: 0.15 | D11: 0.3
A12: Aktif Öğrenme Yayınları | B12: 9. Sınıf | C12: 0.15 | D12: 0.3
A13: Aktif Öğrenme Yayınları | B13: Maarif TYT | C13: 0.15 | D13: 0.3
... A118: Süre Yayınları | B118: Maarif TYT | C118: 0.15 | D118: 0.3

Sheet Tasarım
A1: Tasarım Ayarı | B1: Değer
A2: Başlık | B2: 2026-2027 Öğretmen Fiyat Listesi
A3: Alt Başlık | B3: Dersi seçin, sınıflara ayrılmış kitapları ve fiyatları görüntüleyin.
A4: Ana Renk | B4: #173F5F
A5: Vurgu Rengi | B5: #F2B134

Sheet Kullanım
A1: Fiyat Listesi Yönetim Dosyası
A3: Nasıl kullanılır?
A4: 1 | B4: Yeni ürünü Ürünler sayfasındaki tablonun en altına ekleyin.
A5: 2 | B5: Fiyat sütunu normal satış fiyatıdır.
A6: 3 | B6: İndirimler sayfasında Yayın ve Sınıf bazında Tekli/Toplu indirim oranlarını yazın.
A7: 4 | B7: Ürünler sayfasındaki İnd ve Toplu fiyatlar otomatik hesaplanır.
A8: 5 | B8: Tanıtım Linki varsa kitap adına otomatik olarak bağlanır.
A9: 6 | B9: Dosya GitHub'a yüklendiğinde web programı ve PDF otomatik yenilenir.
A10: 7 | B10: Yeni bir yayınevi ekleyip Güncelle düğmesine bastığınızda Ayarlar listesine otomatik eklenir. Karşısındaki Kitabevi Kodu'nu seçin.
A11: 8 | B11: Logo göstermek için Sayfa Ayarları sayfasındaki Logo Linki alanına doğrudan görsel bağlantısını yapıştırın.

Sheet Ayarlar
A1: Sınıf Ayarları | D1: Kitabevi Listesi | G1: Yayınevi - Kitabevi Eşleştirmesi
A3: Sınıf | B3: Kademe | D3: Kitabevi Kodu | E3: Kitabevi Adı | G3: Yayınevi | H3: Kitabevi Kodu
A4: 5. Sınıf | B4: Ortaokul | D4: kitabevi-1 | E4: İşler Kitabevi | G4: 4K | H4: kitabevi-2
A5: 6. Sınıf | B5: Ortaokul | D5: kitabevi-2 | E5: Mega Kitabevi | G5: Acil Yayınları | H5: kitabevi-1
A6: 7. Sınıf | B6: Ortaokul | G6: Aktif Öğrenme Yayınları | H6: kitabevi-1
A7: 8. Sınıf | B7: Ortaokul | G7: Alan Yayınları | H7: kitabevi-1
A8: 9. Sınıf | B8: Lise | G8: Apotemi Yayınları | H8: kitabevi-1
A9: 10. Sınıf | B9: Lise | G9: Aydın | H9: kitabevi-2
A10: 11. Sınıf | B10: Lise | G10: Bilgi Arşivi Yayınları | H10: kitabevi-1
A11: 12. Sınıf | B11: Lise | G11: Bilgi Sarmal Yayınları | H11: kitabevi-1
A12: Maarif TYT | B12: Lise | G12: Biyotik Yayınları | H12: kitabevi-1
G13: Coğrafya Gurmesi Yayınları | H13: kitabevi-1
G14: Çap Yayınları | H14: kitabevi-1
G15: Edebiyat Sokağı Yayınları | H15: kitabevi-1
G16: Egzersiz Yayınları | H16: kitabevi-1
G17: Eğitim Vadisi | H17: kitabevi-2
G18: ENS Yayınları | H18: kitabevi-1
G19: Etkili Matematik Yayınları | H19: kitabevi-1
G20: Fizik Pedia Yayınları | H20: kitabevi-1
G21: Full Matematik Yayınları | H21: kitabevi-1
G22: Hız ve Renk Yayınları | H22: kitabevi-1
G23: Limit | H23: kitabevi-2
G24: Mikro Orijinal Yayınları | H24: kitabevi-1
... G36: Optik Yayınları | H36: kitabevi-2

Sheet Sayfa Ayarları
A1: Kitabevi Kodu | B1: Kademe | C1: Sayfa Başlığı | D1: Açıklama | E1: Ana Renk | F1: Vurgu Rengi | G1: Aktif | H1: Ana Sayfa Sırası | I1: Logo Linki | J1: Gösterilecek Diğer Liste
A2: kitabevi-1 | B2: Ortaokul | C2: İŞLER KİTABEVİ | D2: Ortaokul kitapları ve güncel fiyat listesi | E2: #8B1E2D | F2: #F2B134 | G2: Evet | H2: 1 | I2: assets/logos/isler-kitabevi.png | J2: kitabevi-2 | Ortaokul
A3: kitabevi-1 | B3: Lise | C3: İŞLER KİTABEVİ | D3: Lise kitapları ve güncel fiyat listesi | E3: #8B1E2D | F3: #F2B134 | G3: Evet | H3: 2 | I3: assets/logos/isler-kitabevi.png | J3: kitabevi-2 | Lise
A4: kitabevi-2 | B4: Ortaokul | C4: MEGA KİTABEVİ | D4: Ortaokul kitapları ve güncel fiyat listesi | E4: #211F20 | F4: #F6B500 | G4: Evet | H4: 3 | I4: assets/logos/mega-kitabevi.png | J4: Yok
A5: kitabevi-2 | B5: Lise | C5: MEGA KİTABEVİ | D5: Lise kitapları ve güncel fiyat listesi | E5: #211F20 | F5: #F6B500 | G5: Evet | H5: 4 | I5: assets/logos/mega-kitabevi.png | J5: Yok

Sheet İletişim
A1: Kitabevi Kodu | B1: Kademe | C1: Ad Soyad | D1: Telefon | E1: WhatsApp
A2: kitabevi-1 | B2: Ortaokul | C2: Aytaç Arslan | D2: 5345556747 | E2: Evet
A3: kitabevi-1 | B3: Ortaokul | C3: Emre Arslan | D3: 5466779329 | E3: Evet
A4: kitabevi-1 | B4: Lise | C4: Aytaç Arslan | D4: 5345556747 | E4: Evet
A5: kitabevi-1 | B5: Lise | C5: Emre Arslan | D5: 5466779329 | E5: Evet
A6: kitabevi-2 | B6: Ortaokul | C6: Furkan ÖZKAN | D6: 5434333319 | E6: Evet
A7: kitabevi-2 | B7: Ortaokul | E7: Evet
A8: kitabevi-2 | B8: Lise | C8: Furkan ÖZKAN | D8: 5434333319 | E8: Evet
A9: kitabevi-2 | B9: Lise | E9: Evet
